Error processing sample p7_R1_mut:
'array_col'

Traceback (most recent call last):
  File "/beegfs/scratch/ric.sessa/kubacki.michal/conda/envs/vpt/lib/python3.10/site-packages/pandas/core/indexes/base.py", line 3812, in get_loc
    return self._engine.get_loc(casted_key)
  File "pandas/_libs/index.pyx", line 167, in pandas._libs.index.IndexEngine.get_loc
  File "pandas/_libs/index.pyx", line 196, in pandas._libs.index.IndexEngine.get_loc
  File "pandas/_libs/hashtable_class_helper.pxi", line 7088, in pandas._libs.hashtable.PyObjectHashTable.get_item
  File "pandas/_libs/hashtable_class_helper.pxi", line 7096, in pandas._libs.hashtable.PyObjectHashTable.get_item
KeyError: 'array_col'

The above exception was the direct cause of the following exception:

Traceback (most recent call last):
  File "/beegfs/scratch/ric.sessa/kubacki.michal/SRF_Linda/SRF_Spatial_segmentation/MERGE_SPATIAL_DATA/./SCRIPTS/marker_genes_per_sample_inclusive_cluster0_recluster.py", line 189, in <module>
    axes[1].scatter(cluster0_subset.obs['array_col'], cluster0_subset.obs['array_row'],
  File "/beegfs/scratch/ric.sessa/kubacki.michal/conda/envs/vpt/lib/python3.10/site-packages/pandas/core/frame.py", line 4107, in __getitem__
    indexer = self.columns.get_loc(key)
  File "/beegfs/scratch/ric.sessa/kubacki.michal/conda/envs/vpt/lib/python3.10/site-packages/pandas/core/indexes/base.py", line 3819, in get_loc
    raise KeyError(key) from err
KeyError: 'array_col'
